[2025-09-22T04:53:01.190+0000] {local_task_job_runner.py:123} INFO - ::group::Pre task execution logs
[2025-09-22T04:53:01.279+0000] {taskinstance.py:2631} INFO - Dependencies all met for dep_context=non-requeueable deps ti=<TaskInstance: create_data.export_file scheduled__2025-09-22T04:52:00+00:00 [queued]>
[2025-09-22T04:53:01.283+0000] {taskinstance.py:2631} INFO - Dependencies all met for dep_context=requeueable deps ti=<TaskInstance: create_data.export_file scheduled__2025-09-22T04:52:00+00:00 [queued]>
[2025-09-22T04:53:01.284+0000] {taskinstance.py:2884} INFO - Starting attempt 1 of 1
[2025-09-22T04:53:01.289+0000] {taskinstance.py:2907} INFO - Executing <Task(_PythonDecoratedOperator): export_file> on 2025-09-22 04:52:00+00:00
[2025-09-22T04:53:01.294+0000] {warnings.py:112} WARNING - /home/***/.local/lib/python3.12/site-packages/***/task/task_runner/standard_task_runner.py:70: DeprecationWarning: This process (pid=111) is multi-threaded, use of fork() may lead to deadlocks in the child.
  pid = os.fork()

[2025-09-22T04:53:01.295+0000] {standard_task_runner.py:72} INFO - Started process 113 to run task
[2025-09-22T04:53:01.295+0000] {standard_task_runner.py:104} INFO - Running: ['***', 'tasks', 'run', 'create_data', 'export_file', 'scheduled__2025-09-22T04:52:00+00:00', '--job-id', '45', '--raw', '--subdir', 'DAGS_FOLDER/add_data.py', '--cfg-path', '/tmp/tmpcdios4vs']
[2025-09-22T04:53:01.296+0000] {standard_task_runner.py:105} INFO - Job 45: Subtask export_file
[2025-09-22T04:53:01.325+0000] {task_command.py:467} INFO - Running <TaskInstance: create_data.export_file scheduled__2025-09-22T04:52:00+00:00 [running]> on host 0aa413b3c501
[2025-09-22T04:53:01.385+0000] {taskinstance.py:3157} INFO - Exporting env vars: AIRFLOW_CTX_DAG_OWNER='***' AIRFLOW_CTX_DAG_ID='create_data' AIRFLOW_CTX_TASK_ID='export_file' AIRFLOW_CTX_EXECUTION_DATE='2025-09-22T04:52:00+00:00' AIRFLOW_CTX_TRY_NUMBER='1' AIRFLOW_CTX_DAG_RUN_ID='scheduled__2025-09-22T04:52:00+00:00'
[2025-09-22T04:53:01.385+0000] {logging_mixin.py:190} INFO - Task instance is in running state
[2025-09-22T04:53:01.386+0000] {logging_mixin.py:190} INFO -  Previous state of the Task instance: queued
[2025-09-22T04:53:01.386+0000] {logging_mixin.py:190} INFO - Current task name:export_file state:running start_date:2025-09-22 04:53:01.280224+00:00
[2025-09-22T04:53:01.386+0000] {logging_mixin.py:190} INFO - Dag name:create_data and current dag run status:running
[2025-09-22T04:53:01.386+0000] {taskinstance.py:740} INFO - ::endgroup::
[2025-09-22T04:53:01.387+0000] {generate_fuel_exports.py:61} INFO - Ensured output directory exists: "/opt/***/data"
[2025-09-22T04:53:01.387+0000] {add_data.py:27} INFO - Generating 300 rows into /opt/***/data
[2025-09-22T04:53:01.416+0000] {generate_fuel_exports.py:161} INFO - Wrote file: /opt/***/data/fuel_export_20250922_045301.parquet | rows=300 | cols=17 | size=34047 bytes
[2025-09-22T04:53:01.416+0000] {add_data.py:30} INFO - File generation completed
[2025-09-22T04:53:01.417+0000] {taskinstance.py:3336} ERROR - Task failed with exception
Traceback (most recent call last):
  File "/home/airflow/.local/lib/python3.12/site-packages/airflow/models/taskinstance.py", line 776, in _execute_task
    result = _execute_callable(context=context, **execute_callable_kwargs)
             ^^^^^^^^^^^^^^^^^^^^^^^^^^^^^^^^^^^^^^^^^^^^^^^^^^^^^^^^^^^^^
  File "/home/airflow/.local/lib/python3.12/site-packages/airflow/models/taskinstance.py", line 742, in _execute_callable
    return ExecutionCallableRunner(
           ^^^^^^^^^^^^^^^^^^^^^^^^
  File "/home/airflow/.local/lib/python3.12/site-packages/airflow/utils/operator_helpers.py", line 252, in run
    return self.func(*args, **kwargs)
           ^^^^^^^^^^^^^^^^^^^^^^^^^^
  File "/home/airflow/.local/lib/python3.12/site-packages/airflow/models/baseoperator.py", line 424, in wrapper
    return func(self, *args, **kwargs)
           ^^^^^^^^^^^^^^^^^^^^^^^^^^^
  File "/home/airflow/.local/lib/python3.12/site-packages/airflow/decorators/base.py", line 266, in execute
    return_value = super().execute(context)
                   ^^^^^^^^^^^^^^^^^^^^^^^^
  File "/home/airflow/.local/lib/python3.12/site-packages/airflow/models/baseoperator.py", line 424, in wrapper
    return func(self, *args, **kwargs)
           ^^^^^^^^^^^^^^^^^^^^^^^^^^^
  File "/home/airflow/.local/lib/python3.12/site-packages/airflow/operators/python.py", line 238, in execute
    return_value = self.execute_callable()
                   ^^^^^^^^^^^^^^^^^^^^^^^
  File "/home/airflow/.local/lib/python3.12/site-packages/airflow/operators/python.py", line 256, in execute_callable
    return runner.run(*self.op_args, **self.op_kwargs)
           ^^^^^^^^^^^^^^^^^^^^^^^^^^^^^^^^^^^^^^^^^^^
  File "/home/airflow/.local/lib/python3.12/site-packages/airflow/utils/operator_helpers.py", line 252, in run
    return self.func(*args, **kwargs)
           ^^^^^^^^^^^^^^^^^^^^^^^^^^
  File "/opt/airflow/dags/add_data.py", line 32, in export_file
    conn = psycopg2.connect(
           ^^^^^^^^^^^^^^^^^
  File "/home/airflow/.local/lib/python3.12/site-packages/psycopg2/__init__.py", line 122, in connect
    conn = _connect(dsn, connection_factory=connection_factory, **kwasync)
           ^^^^^^^^^^^^^^^^^^^^^^^^^^^^^^^^^^^^^^^^^^^^^^^^^^^^^^^^^^^^^^^
psycopg2.OperationalError: connection to server at "localhost" (::1), port 5432 failed: Connection refused
	Is the server running on that host and accepting TCP/IP connections?
connection to server at "localhost" (127.0.0.1), port 5432 failed: Connection refused
	Is the server running on that host and accepting TCP/IP connections?

[2025-09-22T04:53:01.427+0000] {logging_mixin.py:190} INFO - Task instance in failure state
[2025-09-22T04:53:01.428+0000] {logging_mixin.py:190} INFO - Task start:2025-09-22 04:53:01.280224+00:00 end:2025-09-22 04:53:01.427434+00:00 duration:0.14721
[2025-09-22T04:53:01.428+0000] {logging_mixin.py:190} INFO - Task:<Task(_PythonDecoratedOperator): export_file> dag:<DAG: create_data> dagrun:<DagRun create_data @ 2025-09-22 04:52:00+00:00: scheduled__2025-09-22T04:52:00+00:00, state:running, queued_at: 2025-09-22 04:53:00.056189+00:00. externally triggered: False>
[2025-09-22T04:53:01.428+0000] {logging_mixin.py:190} INFO - Failure caused by connection to server at "localhost" (::1), port 5432 failed: Connection refused
	Is the server running on that host and accepting TCP/IP connections?
connection to server at "localhost" (127.0.0.1), port 5432 failed: Connection refused
	Is the server running on that host and accepting TCP/IP connections?
[2025-09-22T04:53:01.428+0000] {taskinstance.py:1242} INFO - Marking task as FAILED. dag_id=create_data, task_id=export_file, run_id=scheduled__2025-09-22T04:52:00+00:00, execution_date=20250922T045200, start_date=20250922T045301, end_date=20250922T045301
[2025-09-22T04:53:01.439+0000] {taskinstance.py:349} INFO - ::group::Post task execution logs
[2025-09-22T04:53:01.440+0000] {standard_task_runner.py:124} ERROR - Failed to execute job 45 for task export_file (connection to server at "localhost" (::1), port 5432 failed: Connection refused
	Is the server running on that host and accepting TCP/IP connections?
connection to server at "localhost" (127.0.0.1), port 5432 failed: Connection refused
	Is the server running on that host and accepting TCP/IP connections?
; 113)
Traceback (most recent call last):
  File "/home/airflow/.local/lib/python3.12/site-packages/airflow/task/task_runner/standard_task_runner.py", line 117, in _start_by_fork
    ret = args.func(args, dag=self.dag)
          ^^^^^^^^^^^^^^^^^^^^^^^^^^^^^
  File "/home/airflow/.local/lib/python3.12/site-packages/airflow/cli/cli_config.py", line 49, in command
    return func(*args, **kwargs)
           ^^^^^^^^^^^^^^^^^^^^^
  File "/home/airflow/.local/lib/python3.12/site-packages/airflow/utils/cli.py", line 116, in wrapper
    return f(*args, **kwargs)
           ^^^^^^^^^^^^^^^^^^
  File "/home/airflow/.local/lib/python3.12/site-packages/airflow/cli/commands/task_command.py", line 483, in task_run
    task_return_code = _run_task_by_selected_method(args, _dag, ti)
                       ^^^^^^^^^^^^^^^^^^^^^^^^^^^^^^^^^^^^^^^^^^^^
  File "/home/airflow/.local/lib/python3.12/site-packages/airflow/cli/commands/task_command.py", line 256, in _run_task_by_selected_method
    return _run_raw_task(args, ti)
           ^^^^^^^^^^^^^^^^^^^^^^^
  File "/home/airflow/.local/lib/python3.12/site-packages/airflow/cli/commands/task_command.py", line 341, in _run_raw_task
    return ti._run_raw_task(
           ^^^^^^^^^^^^^^^^^
  File "/home/airflow/.local/lib/python3.12/site-packages/airflow/utils/session.py", line 97, in wrapper
    return func(*args, session=session, **kwargs)
           ^^^^^^^^^^^^^^^^^^^^^^^^^^^^^^^^^^^^^^
  File "/home/airflow/.local/lib/python3.12/site-packages/airflow/models/taskinstance.py", line 3029, in _run_raw_task
    return _run_raw_task(
           ^^^^^^^^^^^^^^
  File "/home/airflow/.local/lib/python3.12/site-packages/airflow/models/taskinstance.py", line 282, in _run_raw_task
    TaskInstance._execute_task_with_callbacks(
  File "/home/airflow/.local/lib/python3.12/site-packages/airflow/models/taskinstance.py", line 3184, in _execute_task_with_callbacks
    result = self._execute_task(context, task_orig)
             ^^^^^^^^^^^^^^^^^^^^^^^^^^^^^^^^^^^^^^
  File "/home/airflow/.local/lib/python3.12/site-packages/airflow/models/taskinstance.py", line 3208, in _execute_task
    return _execute_task(self, context, task_orig)
           ^^^^^^^^^^^^^^^^^^^^^^^^^^^^^^^^^^^^^^^
  File "/home/airflow/.local/lib/python3.12/site-packages/airflow/models/taskinstance.py", line 776, in _execute_task
    result = _execute_callable(context=context, **execute_callable_kwargs)
             ^^^^^^^^^^^^^^^^^^^^^^^^^^^^^^^^^^^^^^^^^^^^^^^^^^^^^^^^^^^^^
  File "/home/airflow/.local/lib/python3.12/site-packages/airflow/models/taskinstance.py", line 742, in _execute_callable
    return ExecutionCallableRunner(
           ^^^^^^^^^^^^^^^^^^^^^^^^
  File "/home/airflow/.local/lib/python3.12/site-packages/airflow/utils/operator_helpers.py", line 252, in run
    return self.func(*args, **kwargs)
           ^^^^^^^^^^^^^^^^^^^^^^^^^^
  File "/home/airflow/.local/lib/python3.12/site-packages/airflow/models/baseoperator.py", line 424, in wrapper
    return func(self, *args, **kwargs)
           ^^^^^^^^^^^^^^^^^^^^^^^^^^^
  File "/home/airflow/.local/lib/python3.12/site-packages/airflow/decorators/base.py", line 266, in execute
    return_value = super().execute(context)
                   ^^^^^^^^^^^^^^^^^^^^^^^^
  File "/home/airflow/.local/lib/python3.12/site-packages/airflow/models/baseoperator.py", line 424, in wrapper
    return func(self, *args, **kwargs)
           ^^^^^^^^^^^^^^^^^^^^^^^^^^^
  File "/home/airflow/.local/lib/python3.12/site-packages/airflow/operators/python.py", line 238, in execute
    return_value = self.execute_callable()
                   ^^^^^^^^^^^^^^^^^^^^^^^
  File "/home/airflow/.local/lib/python3.12/site-packages/airflow/operators/python.py", line 256, in execute_callable
    return runner.run(*self.op_args, **self.op_kwargs)
           ^^^^^^^^^^^^^^^^^^^^^^^^^^^^^^^^^^^^^^^^^^^
  File "/home/airflow/.local/lib/python3.12/site-packages/airflow/utils/operator_helpers.py", line 252, in run
    return self.func(*args, **kwargs)
           ^^^^^^^^^^^^^^^^^^^^^^^^^^
  File "/opt/airflow/dags/add_data.py", line 32, in export_file
    conn = psycopg2.connect(
           ^^^^^^^^^^^^^^^^^
  File "/home/airflow/.local/lib/python3.12/site-packages/psycopg2/__init__.py", line 122, in connect
    conn = _connect(dsn, connection_factory=connection_factory, **kwasync)
           ^^^^^^^^^^^^^^^^^^^^^^^^^^^^^^^^^^^^^^^^^^^^^^^^^^^^^^^^^^^^^^^
psycopg2.OperationalError: connection to server at "localhost" (::1), port 5432 failed: Connection refused
	Is the server running on that host and accepting TCP/IP connections?
connection to server at "localhost" (127.0.0.1), port 5432 failed: Connection refused
	Is the server running on that host and accepting TCP/IP connections?

[2025-09-22T04:53:01.480+0000] {local_task_job_runner.py:266} INFO - Task exited with return code 1
[2025-09-22T04:53:01.494+0000] {taskinstance.py:3924} INFO - 0 downstream tasks scheduled from follow-on schedule check
[2025-09-22T04:53:01.494+0000] {local_task_job_runner.py:245} INFO - ::endgroup::
